Workbook
Name Slicer_Calculate_Each_Price_Index_Category_Percentage_Value: #N/A
Name Slicer_List_of_Categories: #N/A

Sheet Sheet3
A1: Sector | B1: Year | C1: Month | D1: Cereals and products | E1: Meat and fish | F1: Egg | G1: Milk and products | H1: Oils and fats | I1: Fruits | J1: Vegetables | K1: Pulses and products | L1: Sugar and Confectionery | M1: Spices | N1: Non-alcoholic beverages | O1: Prepared meals, snacks, sweets etc. | P1: Food and beverages | Q1: Housing | R1: Fuel and light | S1: Household goods and services | T1: Health | U1: Transport and communication | V1: Recreation and amusement | W1: Education | X1: Personal care and effects | Y1: Miscellaneous | Z1: General index | AA1: Food | AB1: Energy/Fuel | AC1: Transportation | AD1: Housing | AE1: Healthcare | AF1: Education & Recreation | AG1: Others
A2: Rural | B2: 2022 | C2: September | D2: 162.9 | E2: 206.7 | F2: 169 | G2: 169.5 | H2: 194.1 | I2: 164.1 | J2: 176.9 | K2: 169 | L2: 120.8 | M2: 199.1 | N2: 175.4 | O2: 184.8 | P2: 175.5 | Q2: 162.1 | R2: 179.7 | S2: 173.6 | T2: 180.2 | U2: 166.9 | V2: 170 | W2: 176.2 | X2: 170.8 | Y2: 173.1 | Z2: 176.4 | AA2: =SUM(Table14[[#This Row],[Cereals and products]:[Food and beverages]])/13 -> 174.44615 | AB2: =SUM(Table14[[#This Row],[Fuel and light]]) -> 179.7 | AC2: =SUM(Table14[[#This Row],[Transport and communication]]) -> 166.9 | AD2: =SUM(Table14[[#This Row],[Housing]],Table14[[#This Row],[Household goods and services]])/2 -> 167.85 | AE2: =SUM(Table14[[#This Row],[Health]]) -> 180.2 | AF2: =SUM(Table14[[#This Row],[Recreation and amusement]],Table14[[#This Row],[Education]])/2 -> 173.1 | AG2: =SUM(Table14[[#This Row],[Miscellaneous]],Table14[[#This Row],[Personal care and effects]])/2 -> 171.95
A3: Rural+Urban | B3: 2022 | C3: September | D3: 163.5 | E3: 209.2 | F3: 169.7 | G3: 169.7 | H3: 188.7 | I3: 165.7 | J3: 191.8 | K3: 169.1 | L3: 121.6 | M3: 197.3 | N3: 169.4 | O3: 187.4 | P3: 177.8 | Q3: 169.5 | R3: 179.5 | S3: 169.5 | T3: 177.8 | U3: 162.3 | V3: 167.6 | W3: 173.1 | X3: 170.9 | Y3: 169.7 | Z3: 175.3 | AA3: =SUM(Table14[[#This Row],[Cereals and products]:[Food and beverages]])/13 -> 175.45385 | AB3: =SUM(Table14[[#This Row],[Fuel and light]]) -> 179.5 | AC3: =SUM(Table14[[#This Row],[Transport and communication]]) -> 162.3 | AD3: =SUM(Table14[[#This Row],[Housing]],Table14[[#This Row],[Household goods and services]])/2 -> 169.5 | AE3: =SUM(Table14[[#This Row],[Health]]) -> 177.8 | AF3: =SUM(Table14[[#This Row],[Recreation and amusement]],Table14[[#This Row],[Education]])/2 -> 170.35 | AG3: =SUM(Table14[[#This Row],[Miscellaneous]],Table14[[#This Row],[Personal care and effects]])/2 -> 170.3
A4: Urban | B4: 2022 | C4: September | D4: 164.9 | E4: 213.7 | F4: 170.9 | G4: 170.1 | H4: 179.3 | I4: 167.5 | J4: 220.8 | K4: 169.2 | L4: 123.1 | M4: 193.6 | N4: 161.1 | O4: 190.4 | P4: 181.8 | Q4: 169.5 | R4: 179.2 | S4: 165 | T4: 173.8 | U4: 158.2 | V4: 165.8 | W4: 170.9 | X4: 171.1 | Y4: 166.1 | Z4: 174.1 | AA4: =SUM(Table14[[#This Row],[Cereals and products]:[Food and beverages]])/13 -> 177.41538 | AB4: =SUM(Table14[[#This Row],[Fuel and light]]) -> 179.2 | AC4: =SUM(Table14[[#This Row],[Transport and communication]]) -> 158.2 | AD4: =SUM(Table14[[#This Row],[Housing]],Table14[[#This Row],[Household goods and services]])/2 -> 167.25 | AE4: =SUM(Table14[[#This Row],[Health]]) -> 173.8 | AF4: =SUM(Table14[[#This Row],[Recreation and amusement]],Table14[[#This Row],[Education]])/2 -> 168.35 | AG4: =SUM(Table14[[#This Row],[Miscellaneous]],Table14[[#This Row],[Personal care and effects]])/2 -> 168.6
A5: Rural | B5: 2019 | C5: August | D5: 139.2 | E5: 161.9 | F5: 137.1 | G5: 144.6 | H5: 124.7 | I5: 145.5 | J5: 156.2 | K5: 131.5 | L5: 111.7 | M5: 142.7 | N5: 138.5 | O5: 156.9 | P5: 144 | Q5: =AVERAGE(Q6:Q7) -> 151.6 | R5: 146.4 | S5: 150.2 | T5: 152.7 | U5: 131.4 | V5: 148 | W5: 159.7 | X5: 138.8 | Y5: 144.9 | Z5: 145.7 | AA5: =SUM(Table14[[#This Row],[Cereals and products]:[Food and beverages]])/13 -> 141.11538 | AB5: =SUM(Table14[[#This Row],[Fuel and light]]) -> 146.4 | AC5: =SUM(Table14[[#This Row],[Transport and communication]]) -> 131.4 | AD5: =SUM(Table14[[#This Row],[Housing]],Table14[[#This Row],[Household goods and services]])/2 -> 150.9 | AE5: =SUM(Table14[[#This Row],[Health]]) -> 152.7 | AF5: =SUM(Table14[[#This Row],[Recreation and amusement]],Table14[[#This Row],[Education]])/2 -> 153.85 | AG5: =SUM(Table14[[#This Row],[Miscellaneous]],Table14[[#This Row],[Personal care and effects]])/2 -> 141.85
A6: Rural+Urban | B6: 2019 | C6: August | D6: 140.1 | E6: 160.6 | F6: 138.5 | G6: 144.7 | H6: 122.9 | I6: 149.4 | J6: 167.4 | K6: 130.9 | L6: 112 | M6: 142.6 | N6: 134.9 | O6: 156.6 | P6: 145.9 | Q6: 151.6 | R6: 138.5 | S6: 144.5 | T6: 148.5 | U6: 125.8 | V6: 140.9 | W6: 154.9 | X6: 138.4 | Y6: 140.2 | Z6: 145 | AA6: =SUM(Table14[[#This Row],[Cereals and products]:[Food and beverages]])/13 -> 142.03846 | AB6: =SUM(Table14[[#This Row],[Fuel and light]]) -> 138.5 | AC6: =SUM(Table14[[#This Row],[Transport and communication]]) -> 125.8 | AD6: =SUM(Table14[[#This Row],[Housing]],Table14[[#This Row],[Household goods and services]])/2 -> 148.05 | AE6: =SUM(Table14[[#This Row],[Health]]) -> 148.5 | AF6: =SUM(Table14[[#This Row],[Recreation and amusement]],Table14[[#This Row],[Education]])/2 -> 147.9 | AG6: =SUM(Table14[[#This Row],[Miscellaneous]],Table14[[#This Row],[Personal care and effects]])/2 -> 139.3
A7: Urban | B7: 2019 | C7: August | D7: 142.1 | E7: 158.3 | F7: 140.8 | G7: 144.9 | H7: 119.9 | I7: 153.9 | J7: 189.1 | K7: 129.8 | L7: 112.7 | M7: 142.5 | N7: 129.8 | O7: 156.2 | P7: 149.1 | Q7: 151.6 | R7: 125.5 | S7: 138.1 | T7: 141.5 | U7: 120.8 | V7: 135.4 | W7: 151.5 | X7: 137.8 | Y7: 135.3 | Z7: 144.2 | AA7: =SUM(Table14[[#This Row],[Cereals and products]:[Food and beverages]])/13 -> 143.77692 | AB7: =SUM(Table14[[#This Row],[Fuel and light]]) -> 125.5 | AC7: =SUM(Table14[[#This Row],[Transport and communication]]) -> 120.8 | AD7: =SUM(Table14[[#This Row],[Housing]],Table14[[#This Row],[Household goods and services]])/2 -> 144.85 | AE7: =SUM(Table14[[#This Row],[Health]]) -> 141.5 | AF7: =SUM(Table14[[#This Row],[Recreation and amusement]],Table14[[#This Row],[Education]])/2 -> 143.45 | AG7: =SUM(Table14[[#This Row],[Miscellaneous]],Table14[[#This Row],[Personal care and effects]])/2 -> 136.55
A8: Rural | B8: 2019 | C8: December | D8: 142.8 | E8: 165.3 | F8: 149.5 | G8: 148.7 | H8: 127.5 | I8: 144.3 | J8: 209.5 | K8: 138.8 | L8: 113.6 | M8: 149.1 | N8: 139.3 | O8: 158.3 | P8: 154.3 | Q8: =AVERAGE(Q9:Q10) -> 152.8 | R8: 149.9 | S8: 151.2 | T8: 154.8 | U8: 135 | V8: 149.5 | W8: 161.1 | X8: 140.6 | Y8: 147.1 | Z8: 152.3 | AA8: =SUM(Table14[[#This Row],[Cereals and products]:[Food and beverages]])/13 -> 149.30769 | AB8: =SUM(Table14[[#This Row],[Fuel and light]]) -> 149.9 | AC8: =SUM(Table14[[#This Row],[Transport and communication]]) -> 135 | AD8: =SUM(Table14[[#This Row],[Housing]],Table14[[#This Row],[Household goods and services]])/2 -> 152 | AE8: =SUM(Table14[[#This Row],[Health]]) -> 154.8 | AF8: =SUM(Table14[[#This Row],[Recreation and amusement]],Table14[[#This Row],[Education]])/2 -> 155.3 | AG8: =SUM(Table14[[#This Row],[Miscellaneous]],Table14[[#This Row],[Personal care and effects]])/2 -> 143.85
A9: Rural+Urban | B9: 2019 | C9: December | D9: 143.5 | E9: 165 | F9: 151.1 | G9: 148.3 | H9: 125.7 | I9: 145.7 | J9: 217 | K9: 138.3 | L9: 114 | M9: 148.7 | N9: 135.8 | O9: 158 | P9: 155 | Q9: 152.8 | R9: 143.7 | S9: 145.8 | T9: 150.4 | U9: 129.8 | V9: 142.3 | W9: 155.7 | X9: 140.4 | Y9: 142.5 | Z9: 150.4 | AA9: =SUM(Table14[[#This Row],[Cereals and products]:[Food and beverages]])/13 -> 149.7 | AB9: =SUM(Table14[[#This Row],[Fuel and light]]) -> 143.7 | AC9: =SUM(Table14[[#This Row],[Transport and communication]]) -> 129.8 | AD9: =SUM(Table14[[#This Row],[Housing]],Table14[[#This Row],[Household goods and services]])/2 -> 149.3 | AE9: =SUM(Table14[[#This Row],[Health]]) -> 150.4 | AF9: =SUM(Table14[[#This Row],[Recreation and amusement]],Table14[[#This Row],[Education]])/2 -> 149 | AG9: =SUM(Table14[[#This Row],[Miscellaneous]],Table14[[#This Row],[Personal care and effects]])/2 -> 141.45
A10: Urban | B10: 2019 | C10: December | D10: 144.9 | E10: 164.5 | F10: 153.7 | G10: 147.5 | H10: 122.7 | I10: 147.2 | J10: 231.5 | K10: 137.2 | L10: 114.7 | M10: 148 | N10: 130.8 | O10: 157.7 | P10: 156.3 | Q10: 152.8 | R10: 133.6 | S10: 139.8 | T10: 143.2 | U10: 125.2 | V10: 136.8 | W10: 151.9 | X10: 140.2 | Y10: 137.7 | Z10: 148.3 | AA10: =SUM(Table14[[#This Row],[Cereals and products]:[Food and beverages]])/13 -> 150.51538 | AB10: =SUM(Table14[[#This Row],[Fuel and light]]) -> 133.6 | AC10: =SUM(Table14[[#This Row],[Transport and communication]]) -> 125.2 | AD10: =SUM(Table14[[#This Row],[Housing]],Table14[[#This Row],[Household goods and services]])/2 -> 146.3 | AE10: =SUM(Table14[[#This Row],[Health]]) -> 143.2 | AF10: =SUM(Table14[[#This Row],[Recreation and amusement]],Table14[[#This Row],[Education]])/2 -> 144.35 | AG10: =SUM(Table14[[#This Row],[Miscellaneous]],Table14[[#This Row],[Personal care and effects]])/2 -> 138.95
A11: Rural | B11: 2019 | C11: February | D11: 136.8 | E11: 153 | F11: 139.1 | G11: 142.5 | H11: 124.1 | I11: 135.8 | J11: 128.7 | K11: 121.5 | L11: 108.3 | M11: 139.2 | N11: 137.4 | O11: 156.2 | P11: 137.2 | Q11: =AVERAGE(Q12:Q13) -> 148.5 | R11: 145.3 | S11: 150.1 | T11: 149.9 | U11: 129.2 | V11: 143.4 | W11: 155.5 | X11: 134.9 | Y11: 142.2 | Z11: 141 | AA11: =SUM(Table14[[#This Row],[Cereals and products]:[Food and beverages]])/13 -> 135.36923 | AB11: =SUM(Table14[[#This Row],[Fuel and light]]) -> 145.3 | AC11: =SUM(Table14[[#This Row],[Transport and communication]]) -> 129.2 | AD11: =SUM(Table14[[#This Row],[Housing]],Table14[[#This Row],[Household goods and services]])/2 -> 149.3 | AE11: =SUM(Table14[[#This Row],[Health]]) -> 149.9 | AF11: =SUM(Table14[[#This Row],[Recreation and amusement]],Table14[[#This Row],[Education]])/2 -> 149.45 | AG11: =SUM(Table14[[#This Row],[Miscellaneous]],Table14[[#This Row],[Personal care and effects]])/2 -> 138.55
A12: Rural+Urban | B12: 2019 | C12: February | D12: 137.6 | E12: 152 | F12: 141.5 | G12: 142.2 | H12: 122 | I12: 136.4 | J12: 129.7 | K12: 121 | L12: 109 | M12: 139.7 | N12: 133.6 | O12: 154.9 | P12: 137.5 | Q12: 148.5 | R12: 138.4 | S12: 143.7 | T12: 145.6 | U12: 123.9 | V12: 137.1 | W12: 150.3 | X12: 134.1 | Y12: 137.4 | Z12: 139.9 | AA12: =SUM(Table14[[#This Row],[Cereals and products]:[Food and beverages]])/13 -> 135.16154 | AB12: =SUM(Table14[[#This Row],[Fuel and light]]) -> 138.4 | AC12: =SUM(Table14[[#This Row],[Transport and communication]]) -> 123.9 | AD12: =SUM(Table14[[#This Row],[Housing]],Table14[[#This Row],[Household goods and services]])/2 -> 146.1 | AE12: =SUM(Table14[[#This Row],[Health]]) -> 145.6 | AF12: =SUM(Table14[[#This Row],[Recreation and amusement]],Table14[[#This Row],[Education]])/2 -> 143.7 | AG12: =SUM(Table14[[#This Row],[Miscellaneous]],Table14[[#This Row],[Personal care and effects]])/2 -> 135.75
A13: Urban | B13: 2019 | C13: February | D13: 139.4 | E13: 150.1 | F13: 145.3 | G13: 141.7 | H13: 118.4 | I13: 137 | J13: 131.6 | K13: 119.9 | L13: 110.4 | M13: 140.8 | N13: 128.3 | O13: 153.5 | P13: 138 | Q13: 148.5 | R13: 127.1 | S13: 136.6 | T13: 138.5 | U13: 119.2 | V13: 132.2 | W13: 146.6 | X13: 133 | Y13: 132.4 | Z13: 138.6 | AA13: =SUM(Table14[[#This Row],[Cereals and products]:[Food and beverages]])/13 -> 134.95385 | AB13: =SUM(Table14[[#This Row],[Fuel and light]]) -> 127.1 | AC13: =SUM(Table14[[#This Row],[Transport and communication]]) -> 119.2 | AD13: =SUM(Table14[[#This Row],[Housing]],Table14[[#This Row],[Household goods and services]])/2 -> 142.55 | AE13: =SUM(Table14[[#This Row],[Health]]) -> 138.5 | AF13: =SUM(Table14[[#This Row],[Recreation and amusement]],Table14[[#This Row],[Education]])/2 -> 139.4 | AG13: =SUM(Table14[[#This Row],[Miscellaneous]],Table14[[#This Row],[Personal care and effects]])/2 -> 132.7
A14: Urban | B14: 2018 | C14: September | D14: 137 | E14: 143.1 | F14: 132.8 | G14: 141.5 | H14: 117.8 | I14: 140 | J14: 151.3 | K14: 113.5 | L14: 112.3 | M14: 141.2 | N14: 127.7 | O14: 151.3 | P14: 138.9 | Q14: 145.3 | R14: 131.2 | S14: 134.9 | T14: 135.7 | U14: 122.5 | V14: 130.2 | W14: 145.2 | X14: 129.3 | Y14: 131.9 | Z14: 138.1 | AA14: =SUM(Table14[[#This Row],[Cereals and products]:[Food and beverages]])/13 -> 134.49231 | AB14: =SUM(Table14[[#This Row],[Fuel and light]]) -> 131.2 | AC14: =SUM(Table14[[#This Row],[Transport and communication]]) -> 122.5 | AD14: =SUM(Table14[[#This Row],[Housing]],Table14[[#This Row],[Household goods and services]])/2 -> 140.1 | AE14: =SUM(Table14[[#This Row],[Health]]) -> 135.7 | AF14: =SUM(Table14[[#This Row],[Recreation and amusement]],Table14[[#This Row],[Education]])/2 -> 137.7 | AG14: =SUM(Table14[[#This Row],[Miscellaneous]],Table14[[#This Row],[Personal care and effects]])/2 -> 130.6
A15: Rural+Urban | B15: 2018 | C15: September | D15: 138.6 | E15: 145.8 | F15: 135.1 | G15: 142.9 | H15: 122.1 | I15: 145.4 | J15: 150 | K15: 121.4 | L15: 113.7 | M15: 139.5 | N15: 130.8 | O15: 153.8 | P15: 140.4 | Q15: 145.3 | R15: 142.3 | S15: 139.7 | T15: 138.4 | U15: 126 | V15: 134.5 | W15: 146.2 | X15: 130.9 | Y15: 134.7 | Z15: 140.2 | AA15: =SUM(Table14[[#This Row],[Cereals and products]:[Food and beverages]])/13 -> 136.88462 | AB15: =SUM(Table14[[#This Row],[Fuel and light]]) -> 142.3 | AC15: =SUM(Table14[[#This Row],[Transport and communication]]) -> 126 | AD15: =SUM(Table14[[#This Row],[Housing]],Table14[[#This Row],[Household goods and services]])/2 -> 142.5 | AE15: =SUM(Table14[[#This Row],[Health]]) -> 138.4 | AF15: =SUM(Table14[[#This Row],[Recreation and amusement]],Table14[[#This Row],[Education]])/2 -> 140.35 | AG15: =SUM(Table14[[#This Row],[Miscellaneous]],Table14[[#This Row],[Personal care and effects]])/2 -> 132.8
A16: Rural | B16: 2018 | C16: September | D16: 139.4 | E16: 147.2 | F16: 136.6 | G16: 143.7 | H16: 124.6 | I16: 150.1 | J16: 149.4 | K16: 125.4 | L16: 114.4 | M16: 138.7 | N16: 133.1 | O16: 155.9 | P16: 141.3 | Q16: 145.3 | R16: 149 | S16: 144 | T16: 140 | U16: 129.9 | V16: 140 | W16: 147.6 | X16: 132 | Y16: 137.4 | Z16: 142.1 | AA16: =SUM(Table14[[#This Row],[Cereals and products]:[Food and beverages]])/13 -> 138.44615 | AB16: =SUM(Table14[[#This Row],[Fuel and light]]) -> 149 | AC16: =SUM(Table14[[#This Row],[Transport and communication]]) -> 129.9 | AD16: =SUM(Table14[[#This Row],[Housing]],Table14[[#This Row],[Household goods and services]])/2 -> 144.65 | AE16: =SUM(Table14[[#This Row],[Health]]) -> 140 | AF16: =SUM(Table14[[#This Row],[Recreation and amusement]],Table14[[#This Row],[Education]])/2 -> 143.8 | AG16: =SUM(Table14[[#This Row],[Miscellaneous]],Table14[[#This Row],[Personal care and effects]])/2 -> 134.7
A17: Urban | B17: 2017 | C17: September | D17: 133.6 | E17: 143 | F17: 129.7 | G17: 138.7 | H17: 114.5 | I17: 137.5 | J17: 160.7 | K17: 124.5 | L17: 122.4 | M17: 137.3 | N17: 124.8 | O17: 145 | P17: 138 | Q17: 135.7 | R17: 120.6 | S17: 128.1 | T17: 126.1 | U17: 115.7 | V17: 124.5 | W17: 135.9 | X17: 124.4 | Y17: 124.5 | Z17: 132.4 | AA17: =SUM(Table14[[#This Row],[Cereals and products]:[Food and beverages]])/13 -> 134.59231 | AB17: =SUM(Table14[[#This Row],[Fuel and light]]) -> 120.6 | AC17: =SUM(Table14[[#This Row],[Transport and communication]]) -> 115.7 | AD17: =SUM(Table14[[#This Row],[Housing]],Table14[[#This Row],[Household goods and services]])/2 -> 131.9 | AE17: =SUM(Table14[[#This Row],[Health]]) -> 126.1 | AF17: =SUM(Table14[[#This Row],[Recreation and amusement]],Table14[[#This Row],[Education]])/2 -> 130.2 | AG17: =SUM(Table14[[#This Row],[Miscellaneous]],Table14[[#This Row],[Personal care and effects]])/2 -> 124.45
A18: Rural+Urban | B18: 2017 | C18: September | D18: 134.7 | E18: 142.4 | F18: 130.2 | G18: 139.6 | H18: 118.4 | I18: 143 | J18: 156.6 | K18: 132.9 | L18: 121.5 | M18: 135.6 | N18: 128.8 | O18: 147.3 | P18: 139 | Q18: 135.7 | R18: 131 | S18: 133.3 | T18: 130.6 | U18: 118.3 | V18: 127.9 | W18: 137.4 | X18: 125.7 | Y18: 127.5 | Z18: 135.2 | AA18: =SUM(Table14[[#This Row],[Cereals and products]:[Food and beverages]])/13 -> 136.15385 | AB18: =SUM(Table14[[#This Row],[Fuel and light]]) -> 131 | AC18: =SUM(Table14[[#This Row],[Transport and communication]]) -> 118.3 | AD18: =SUM(Table14[[#This Row],[Housing]],Table14[[#This Row],[Household goods and services]])/2 -> 134.5 | AE18: =SUM(Table14[[#This Row],[Health]]) -> 130.6 | AF18: =SUM(Table14[[#This Row],[Recreation and amusement]],Table14[[#This Row],[Education]])/2 -> 132.65 | AG18: =SUM(Table14[[#This Row],[Miscellaneous]],Table14[[#This Row],[Personal care and effects]])/2 -> 126.6
A19: Rural | B19: 2017 | C19: September | D19: 135.2 | E19: 142 | F19: 130.5 | G19: 140.2 | H19: 120.7 | I19: 147.8 | J19: 154.5 | K19: 137.1 | L19: 121 | M19: 134.7 | N19: 131.7 | O19: 149.3 | P19: 139.6 | Q19: 135.7 | R19: 137.4 | S19: 137.9 | T19: 133.4 | U19: 121.2 | V19: 132.3 | W19: 139.6 | X19: 126.7 | Y19: 130.3 | Z19: 137.6 | AA19: =SUM(Table14[[#This Row],[Cereals and products]:[Food and beverages]])/13 -> 137.25385 | AB19: =SUM(Table14[[#This Row],[Fuel and light]]) -> 137.4 | AC19: =SUM(Table14[[#This Row],[Transport and communication]]) -> 121.2 | AD19: =SUM(Table14[[#This Row],[Housing]],Table14[[#This Row],[Household goods and services]])/2 -> 136.8 | AE19: =SUM(Table14[[#This Row],[Health]]) -> 133.4 | AF19: =SUM(Table14[[#This Row],[Recreation and amusement]],Table14[[#This Row],[Education]])/2 -> 135.95 | AG19: =SUM(Table14[[#This Row],[Miscellaneous]],Table14[[#This Row],[Personal care and effects]])/2 -> 128.5
A20: Urban | B20: 2016 | C20: September | D20: 128.1 | E20: 137.7 | F20: 130.6 | G20: 132.6 | H20: 111.9 | I20: 132.5 | J20: 152.9 | K20: 173.6 | L20: 115.1 | M20: 144.8 | N20: 122.1 | O20: 138.8 | P20: 135.7 | Q20: 127.9 | R20: 114.8 | S20: 124.3 | T20: 121.4 | U20: 111.8 | V20: 120.8 | W20: 131.6 | X20: 121.2 | Y20: 120.5 | Z20: 128 | AA20: =SUM(Table14[[#This Row],[Cereals and products]:[Food and beverages]])/13 -> 135.10769 | AB20: =SUM(Table14[[#This Row],[Fuel and light]]) -> 114.8 | AC20: =SUM(Table14[[#This Row],[Transport and communication]]) -> 111.8 | AD20: =SUM(Table14[[#This Row],[Housing]],Table14[[#This Row],[Household goods and services]])/2 -> 126.1 | AE20: =SUM(Table14[[#This Row],[Health]]) -> 121.4 | AF20: =SUM(Table14[[#This Row],[Recreation and amusement]],Table14[[#This Row],[Education]])/2 -> 126.2 | AG20: =SUM(Table14[[#This Row],[Miscellaneous]],Table14[[#This Row],[Personal care and effects]])/2 -> 120.85
A21: Rural+Urban | B21: 2016 | C21: September | D21: 129.9 | E21: 138 | F21: 130.5 | G21: 134.4 | H21: 117.2 | I21: 136.1 | J21: 150.7 | K21: 171.5 | L21: 113.8 | M21: 138.8 | N21: 126 | O21: 140.2 | P21: 136.6 | Q21: 127.9 | R21: 124.1 | S21: 127.9 | T21: 125.4 | U21: 114.3 | V21: 122.9 | W21: 131.8 | X21: 122.1 | Y21: 122.8 | Z21: 130.9 | AA21: =SUM(Table14[[#This Row],[Cereals and products]:[Food and beverages]])/13 -> 135.66923 | AB21: =SUM(Table14[[#This Row],[Fuel and light]]) -> 124.1 | AC21: =SUM(Table14[[#This Row],[Transport and communication]]) -> 114.3 | AD21: =SUM(Table14[[#This Row],[Housing]],Table14[[#This Row],[Household goods and services]])/2 -> 127.9 | AE21: =SUM(Table14[[#This Row],[Health]]) -> 125.4 | AF21: =SUM(Table14[[#This Row],[Recreation and amusement]],Table14[[#This Row],[Education]])/2 -> 127.35 | AG21: =SUM(Table14[[#This Row],[Miscellaneous]],Table14[[#This Row],[Personal care and effects]])/2 -> 122.45
A22: Rural | B22: 2016 | C22: September | D22: 130.8 | E22: 138.2 | F22: 130.5 | G22: 135.5 | H22: 120.2 | I22: 139.2 | J22: 149.5 | K22: 170.4 | L22: 113.1 | M22: 135.8 | N22: 128.8 | O22: 141.5 | P22: 137.2 | Q22: 127.9 | R22: 129.7 | S22: 131.1 | T22: 127.8 | U22: 117 | V22: 125.7 | W22: 132.2 | X22: 122.8 | Y22: 124.9 | Z22: 133.4 | AA22: =SUM(Table14[[#This Row],[Cereals and products]:[Food and beverages]])/13 -> 136.20769 | AB22: =SUM(Table14[[#This Row],[Fuel and light]]) -> 129.7 | AC22: =SUM(Table14[[#This Row],[Transport and communication]]) -> 117 | AD22: =SUM(Table14[[#This Row],[Housing]],Table14[[#This Row],[Household goods and services]])/2 -> 129.5 | AE22: =SUM(Table14[[#This Row],[Health]]) -> 127.8 | AF22: =SUM(Table14[[#This Row],[Recreation and amusement]],Table14[[#This Row],[Education]])/2 -> 128.95 | AG22: =SUM(Table14[[#This Row],[Miscellaneous]],Table14[[#This Row],[Personal care and effects]])/2 -> 123.85
A23: Urban | B23: 2015 | C23: September | D23: 123.4 | E23: 129 | F23: 115.6 | G23: 128.3 | H23: 107 | I23: 124 | J23: 168.5 | K23: 165.4 | L23: 86.3 | M23: 134.4 | N23: 119.1 | O23: 132.3 | P23: 131.5 | Q23: 121.6 | R23: 115.1 | S23: 120.4 | T23: 117.1 | U23: 109.1 | V23: 117.3 | W23: 126.5 | X23: 112.9 | Y23: 116.2 | Z23: 123.5 | AA23: =SUM(Table14[[#This Row],[Cereals and products]:[Food and beverages]])/13 -> 128.06154 | AB23: =SUM(Table14[[#This Row],[Fuel and light]]) -> 115.1 | AC23: =SUM(Table14[[#This Row],[Transport and communication]]) -> 109.1 | AD23: =SUM(Table14[[#This Row],[Housing]],Table14[[#This Row],[Household goods and services]])/2 -> 121 | AE23: =SUM(Table14[[#This Row],[Health]]) -> 117.1 | AF23: =SUM(Table14[[#This Row],[Recreation and amusement]],Table14[[#This Row],[Education]])/2 -> 121.9 | AG23: =SUM(Table14[[#This Row],[Miscellaneous]],Table14[[#This Row],[Personal care and effects]])/2 -> 114.55
... A34: Urban | B34: 2022 | C34: October | D34: 166.4 | E34: 214.9 | F34: 171.9 | G34: 171 | H34: 177.7 | I34: 165.7 | J34: 228.6 | K34: 169.9 | L34: 123.4 | M34: 196.4 | N34: 161.6 | O34: 191.5 | P34: 183.3 | Q34: 171.2 | R34: 180 | S34: 166 | T34: 174.7 | U34: 158.8 | V34: 166.3 | W34: 171.2 | X34: 172.3 | Y34: 166.8 | Z34: 175.3 | AA34: =SUM(Table14[[#This Row],[Cereals and products]:[Food and beverages]])/13 -> 178.63846 | AB34: =SUM(Table14[[#This Row],[Fuel and light]]) -> 180 | AC34: =SUM(Table14[[#This Row],[Transport and communication]]) -> 158.8 | AD34: =SUM(Table14[[#This Row],[Housing]],Table14[[#This Row],[Household goods and services]])/2 -> 168.6 | AE34: =SUM(Table14[[#This Row],[Health]]) -> 174.7 | AF34: =SUM(Table14[[#This Row],[Recreation and amusement]],Table14[[#This Row],[Education]])/2 -> 168.75 | AG34: =SUM(Table14[[#This Row],[Miscellaneous]],Table14[[#This Row],[Personal care and effects]])/2 -> 169.55
A35: Rural | B35: 2019 | C35: January | D35: 136.6 | E35: 152.5 | F35: 138.2 | G35: 142.4 | H35: 123.9 | I35: 135.5 | J35: 131.7 | K35: 121.3 | L35: 108.4 | M35: 138.9 | N35: 137 | O35: 155.8 | P35: 137.4 | Q35: =AVERAGE(Q36:Q37) -> 147.7 | R35: 146.2 | S35: 150.1 | T35: 149.6 | U35: 128.6 | V35: 142.9 | W35: 155.2 | X35: 133.5 | Y35: 141.7 | Z35: 141 | AA35: =SUM(Table14[[#This Row],[Cereals and products]:[Food and beverages]])/13 -> 135.35385 | AB35: =SUM(Table14[[#This Row],[Fuel and light]]) -> 146.2 | AC35: =SUM(Table14[[#This Row],[Transport and communication]]) -> 128.6 | AD35: =SUM(Table14[[#This Row],[Housing]],Table14[[#This Row],[Household goods and services]])/2 -> 148.9 | AE35: =SUM(Table14[[#This Row],[Health]]) -> 149.6 | AF35: =SUM(Table14[[#This Row],[Recreation and amusement]],Table14[[#This Row],[Education]])/2 -> 149.05 | AG35: =SUM(Table14[[#This Row],[Miscellaneous]],Table14[[#This Row],[Personal care and effects]])/2 -> 137.6
A36: Rural+Urban | B36: 2019 | C36: January | D36: 137.1 | E36: 151.4 | F36: 140.2 | G36: 142.1 | H36: 121.8 | I36: 135.4 | J36: 131.3 | K36: 120.3 | L36: 109.1 | M36: 139.4 | N36: 133.3 | O36: 154.6 | P36: 137.4 | Q36: 147.7 | R36: 139.5 | S36: 143.6 | T36: 145.1 | U36: 123.3 | V36: 136.7 | W36: 150.2 | X36: 132.8 | Y36: 136.9 | Z36: 139.6 | AA36: =SUM(Table14[[#This Row],[Cereals and products]:[Food and beverages]])/13 -> 134.87692 | AB36: =SUM(Table14[[#This Row],[Fuel and light]]) -> 139.5 | AC36: =SUM(Table14[[#This Row],[Transport and communication]]) -> 123.3 | AD36: =SUM(Table14[[#This Row],[Housing]],Table14[[#This Row],[Household goods and services]])/2 -> 145.65 | AE36: =SUM(Table14[[#This Row],[Health]]) -> 145.1 | AF36: =SUM(Table14[[#This Row],[Recreation and amusement]],Table14[[#This Row],[Education]])/2 -> 143.45 | AG36: =SUM(Table14[[#This Row],[Miscellaneous]],Table14[[#This Row],[Personal care and effects]])/2 -> 134.85
A37: Urban | B37: 2019 | C37: January | D37: 138.3 | E37: 149.4 | F37: 143.5 | G37: 141.7 | H37: 118.1 | I37: 135.2 | J37: 130.5 | K37: 118.2 | L37: 110.4 | M37: 140.4 | N37: 128.1 | O37: 153.2 | P37: 137.3 | Q37: 147.7 | R37: 128.6 | S37: 136.3 | T37: 137.8 | U37: 118.6 | V37: 131.9 | W37: 146.6 | X37: 131.7 | Y37: 131.8 | Z37: 138 | AA37: =SUM(Table14[[#This Row],[Cereals and products]:[Food and beverages]])/13 -> 134.17692 | AB37: =SUM(Table14[[#This Row],[Fuel and light]]) -> 128.6 | AC37: =SUM(Table14[[#This Row],[Transport and communication]]) -> 118.6 | AD37: =SUM(Table14[[#This Row],[Housing]],Table14[[#This Row],[Household goods and services]])/2 -> 142 | AE37: =SUM(Table14[[#This Row],[Health]]) -> 137.8 | AF37: =SUM(Table14[[#This Row],[Recreation and amusement]],Table14[[#This Row],[Education]])/2 -> 139.25 | AG37: =SUM(Table14[[#This Row],[Miscellaneous]],Table14[[#This Row],[Personal care and effects]])/2 -> 131.75
A38: Rural | B38: 2019 | C38: July | D38: 138.4 | E38: 164 | F38: 138.4 | G38: 143.9 | H38: 124.4 | I38: 146.4 | J38: 150.1 | K38: 130.6 | L38: 110.8 | M38: 141.7 | N38: 138.5 | O38: 156.7 | P38: 143 | Q38: =AVERAGE(Q39:Q40) -> 150.6 | R38: 146.8 | S38: 150 | T38: 152.2 | U38: 131.2 | V38: 147.5 | W38: 159.1 | X38: 136.1 | Y38: 144.2 | Z38: 144.9 | AA38: =SUM(Table14[[#This Row],[Cereals and products]:[Food and beverages]])/13 -> 140.53077 | AB38: =SUM(Table14[[#This Row],[Fuel and light]]) -> 146.8 | AC38: =SUM(Table14[[#This Row],[Transport and communication]]) -> 131.2 | AD38: =SUM(Table14[[#This Row],[Housing]],Table14[[#This Row],[Household goods and services]])/2 -> 150.3 | AE38: =SUM(Table14[[#This Row],[Health]]) -> 152.2 | AF38: =SUM(Table14[[#This Row],[Recreation and amusement]],Table14[[#This Row],[Education]])/2 -> 153.3 | AG38: =SUM(Table14[[#This Row],[Miscellaneous]],Table14[[#This Row],[Personal care and effects]])/2 -> 140.15
A39: Rural+Urban | B39: 2019 | C39: July | D39: 139.3 | E39: 162.7 | F39: 140 | G39: 144 | H39: 122.5 | I39: 150.3 | J39: 160.3 | K39: 130 | L39: 111.1 | M39: 141.7 | N39: 134.7 | O39: 156.2 | P39: 144.7 | Q39: 150.6 | R39: 139.3 | S39: 144.2 | T39: 147.9 | U39: 125.6 | V39: 140.5 | W39: 154 | X39: 135.7 | Y39: 139.5 | Z39: 144.2 | AA39: =SUM(Table14[[#This Row],[Cereals and products]:[Food and beverages]])/13 -> 141.34615 | AB39: =SUM(Table14[[#This Row],[Fuel and light]]) -> 139.3 | AC39: =SUM(Table14[[#This Row],[Transport and communication]]) -> 125.6 | AD39: =SUM(Table14[[#This Row],[Housing]],Table14[[#This Row],[Household goods and services]])/2 -> 147.4 | AE39: =SUM(Table14[[#This Row],[Health]]) -> 147.9 | AF39: =SUM(Table14[[#This Row],[Recreation and amusement]],Table14[[#This Row],[Education]])/2 -> 147.25 | AG39: =SUM(Table14[[#This Row],[Miscellaneous]],Table14[[#This Row],[Personal care and effects]])/2 -> 137.6
A40: Urban | B40: 2019 | C40: July | D40: 141.4 | E40: 160.2 | F40: 142.5 | G40: 144.1 | H40: 119.3 | I40: 154.7 | J40: 180.1 | K40: 128.9 | L40: 111.8 | M40: 141.6 | N40: 129.5 | O40: 155.6 | P40: 147.7 | Q40: 150.6 | R40: 127 | S40: 137.7 | T40: 140.8 | U40: 120.6 | V40: 135 | W40: 150.4 | X40: 135.1 | Y40: 134.5 | Z40: 143.3 | AA40: =SUM(Table14[[#This Row],[Cereals and products]:[Food and beverages]])/13 -> 142.87692 | AB40: =SUM(Table14[[#This Row],[Fuel and light]]) -> 127 | AC40: =SUM(Table14[[#This Row],[Transport and communication]]) -> 120.6 | AD40: =SUM(Table14[[#This Row],[Housing]],Table14[[#This Row],[Household goods and services]])/2 -> 144.15 | AE40: =SUM(Table14[[#This Row],[Health]]) -> 140.8 | AF40: =SUM(Table14[[#This Row],[Recreation and amusement]],Table14[[#This Row],[Education]])/2 -> 142.7 | AG40: =SUM(Table14[[#This Row],[Miscellaneous]],Table14[[#This Row],[Personal care and effects]])/2 -> 134.8
A41: Rural | B41: 2019 | C41: June | D41: 137.8 | E41: 163.5 | F41: 136.2 | G41: 143.2 | H41: 124.3 | I41: 143.3 | J41: 140.6 | K41: 128.7 | L41: 110.6 | M41: 140.4 | N41: 138 | O41: 156.6 | P41: 141 | Q41: =AVERAGE(Q42:Q43) -> 149.4 | R41: 147.8 | S41: 149.6 | T41: 151.7 | U41: 130.2 | V41: 146.4 | W41: 157.7 | X41: 134.8 | Y41: 143.3 | Z41: 143.6 | AA41: =SUM(Table14[[#This Row],[Cereals and products]:[Food and beverages]])/13 -> 138.78462 | AB41: =SUM(Table14[[#This Row],[Fuel and light]]) -> 147.8 | AC41: =SUM(Table14[[#This Row],[Transport and communication]]) -> 130.2 | AD41: =SUM(Table14[[#This Row],[Housing]],Table14[[#This Row],[Household goods and services]])/2 -> 149.5 | AE41: =SUM(Table14[[#This Row],[Health]]) -> 151.7 | AF41: =SUM(Table14[[#This Row],[Recreation and amusement]],Table14[[#This Row],[Education]])/2 -> 152.05 | AG41: =SUM(Table14[[#This Row],[Miscellaneous]],Table14[[#This Row],[Personal care and effects]])/2 -> 139.05
A42: Rural+Urban | B42: 2019 | C42: June | D42: 138.7 | E42: 162.1 | F42: 137.8 | G42: 143.3 | H42: 122.2 | I42: 146.8 | J42: 150.5 | K42: 128.3 | L42: 111 | M42: 140.6 | N42: 134.2 | O42: 155.9 | P42: 142.7 | Q42: 149.4 | R42: 141.2 | S42: 143.8 | T42: 147.4 | U42: 124.6 | V42: 139.6 | W42: 152.5 | X42: 134.3 | Y42: 138.6 | Z42: 142.9 | AA42: =SUM(Table14[[#This Row],[Cereals and products]:[Food and beverages]])/13 -> 139.54615 | AB42: =SUM(Table14[[#This Row],[Fuel and light]]) -> 141.2 | AC42: =SUM(Table14[[#This Row],[Transport and communication]]) -> 124.6 | AD42: =SUM(Table14[[#This Row],[Housing]],Table14[[#This Row],[Household goods and services]])/2 -> 146.6 | AE42: =SUM(Table14[[#This Row],[Health]]) -> 147.4 | AF42: =SUM(Table14[[#This Row],[Recreation and amusement]],Table14[[#This Row],[Education]])/2 -> 146.05 | AG42: =SUM(Table14[[#This Row],[Miscellaneous]],Table14[[#This Row],[Personal care and effects]])/2 -> 136.45
A43: Urban | B43: 2019 | C43: June | D43: 140.7 | E43: 159.6 | F43: 140.4 | G43: 143.4 | H43: 118.6 | I43: 150.9 | J43: 169.8 | K43: 127.4 | L43: 111.8 | M43: 141 | N43: 129 | O43: 155.1 | P43: 145.6 | Q43: 149.4 | R43: 130.5 | S43: 137.4 | T43: 140.3 | U43: 119.6 | V43: 134.3 | W43: 148.9 | X43: 133.7 | Y43: 133.6 | Z43: 142.1 | AA43: =SUM(Table14[[#This Row],[Cereals and products]:[Food and beverages]])/13 -> 141.02308 | AB43: =SUM(Table14[[#This Row],[Fuel and light]]) -> 130.5 | AC43: =SUM(Table14[[#This Row],[Transport and communication]]) -> 119.6 | AD43: =SUM(Table14[[#This Row],[Housing]],Table14[[#This Row],[Household goods and services]])/2 -> 143.4 | AE43: =SUM(Table14[[#This Row],[Health]]) -> 140.3 | AF43: =SUM(Table14[[#This Row],[Recreation and amusement]],Table14[[#This Row],[Education]])/2 -> 141.6 | AG43: =SUM(Table14[[#This Row],[Miscellaneous]],Table14[[#This Row],[Personal care and effects]])/2 -> 133.65
A44: Rural+Urban | B44: 2018 | C44: October | D44: 137.4 | E44: 149.5 | F44: 137.3 | G44: 141.9 | H44: 121.1 | I44: 142.5 | J44: 146.7 | K44: 119.1 | L44: 111.9 | M44: 141 | N44: 133.6 | O44: 154.5 | P44: 139.7 | Q44: 146.9 | R44: 145.3 | S44: 142.2 | T44: 142.1 | U44: 125.5 | V44: 136.5 | W44: 147.8 | X44: 132 | Y44: 136.3 | Z44: 140.8 | AA44: =SUM(Table14[[#This Row],[Cereals and products]:[Food and beverages]])/13 -> 136.63077 | AB44: =SUM(Table14[[#This Row],[Fuel and light]]) -> 145.3 | AC44: =SUM(Table14[[#This Row],[Transport and communication]]) -> 125.5 | AD44: =SUM(Table14[[#This Row],[Housing]],Table14[[#This Row],[Household goods and services]])/2 -> 144.55 | AE44: =SUM(Table14[[#This Row],[Health]]) -> 142.1 | AF44: =SUM(Table14[[#This Row],[Recreation and amusement]],Table14[[#This Row],[Education]])/2 -> 142.15 | AG44: =SUM(Table14[[#This Row],[Miscellaneous]],Table14[[#This Row],[Personal care and effects]])/2 -> 134.15
A45: Urban | B45: 2018 | C45: October | D45: 137.6 | E45: 144.9 | F45: 133.5 | G45: 141.5 | H45: 118 | I45: 139.5 | J45: 153 | K45: 113.2 | L45: 112.8 | M45: 141.1 | N45: 127.6 | O45: 152 | P45: 139.4 | Q45: 146.3 | R45: 133.4 | S45: 135.1 | T45: 136.2 | U45: 123.3 | V45: 130.7 | W45: 145.5 | X45: 130.4 | Y45: 132.5 | Z45: 138.9 | AA45: =SUM(Table14[[#This Row],[Cereals and products]:[Food and beverages]])/13 -> 134.93077 | AB45: =SUM(Table14[[#This Row],[Fuel and light]]) -> 133.4 | AC45: =SUM(Table14[[#This Row],[Transport and communication]]) -> 123.3 | AD45: =SUM(Table14[[#This Row],[Housing]],Table14[[#This Row],[Household goods and services]])/2 -> 140.7 | AE45: =SUM(Table14[[#This Row],[Health]]) -> 136.2 | AF45: =SUM(Table14[[#This Row],[Recreation and amusement]],Table14[[#This Row],[Education]])/2 -> 138.1 | AG45: =SUM(Table14[[#This Row],[Miscellaneous]],Table14[[#This Row],[Personal care and effects]])/2 -> 131.45
A46: Rural | B46: 2018 | C46: October | D46: 139.3 | E46: 147.6 | F46: 134.6 | G46: 141.9 | H46: 123.5 | I46: 144.5 | J46: 147.6 | K46: 121.4 | L46: 112.3 | M46: 139.5 | N46: 134.6 | O46: 155.2 | P46: 140.2 | Q46: 146.6 | R46: 149.7 | S46: 147.5 | T46: 144.8 | U46: 130.8 | V46: 140.1 | W46: 148 | X46: 134.4 | Y46: 139.8 | Z46: 142.2 | AA46: =SUM(Table14[[#This Row],[Cereals and products]:[Food and beverages]])/13 -> 137.09231 | AB46: =SUM(Table14[[#This Row],[Fuel and light]]) -> 149.7 | AC46: =SUM(Table14[[#This Row],[Transport and communication]]) -> 130.8 | AD46: =SUM(Table14[[#This Row],[Housing]],Table14[[#This Row],[Household goods and services]])/2 -> 147.05 | AE46: =SUM(Table14[[#This Row],[Health]]) -> 144.8 | AF46: =SUM(Table14[[#This Row],[Recreation and amusement]],Table14[[#This Row],[Education]])/2 -> 144.05 | AG46: =SUM(Table14[[#This Row],[Miscellaneous]],Table14[[#This Row],[Personal care and effects]])/2 -> 137.1
A47: Urban | B47: 2017 | C47: October | D47: 133.9 | E47: 142.8 | F47: 131.4 | G47: 139.1 | H47: 114.9 | I47: 135.6 | J47: 173.2 | K47: 124.1 | L47: 122.6 | M47: 137.8 | N47: 125.1 | O47: 145.5 | P47: 139.7 | Q47: 137.3 | R47: 122.6 | S47: 128.3 | T47: 126.6 | U47: 115 | V47: 124.8 | W47: 136.3 | X47: 124.6 | Y47: 124.5 | Z47: 133.5 | AA47: =SUM(Table14[[#This Row],[Cereals and products]:[Food and beverages]])/13 -> 135.82308 | AB47: =SUM(Table14[[#This Row],[Fuel and light]]) -> 122.6 | AC47: =SUM(Table14[[#This Row],[Transport and communication]]) -> 115 | AD47: =SUM(Table14[[#This Row],[Housing]],Table14[[#This Row],[Household goods and services]])/2 -> 132.8 | AE47: =SUM(Table14[[#This Row],[Health]]) -> 126.6 | AF47: =SUM(Table14[[#This Row],[Recreation and amusement]],Table14[[#This Row],[Education]])/2 -> 130.55 | AG47: =SUM(Table14[[#This Row],[Miscellaneous]],Table14[[#This Row],[Personal care and effects]])/2 -> 124.55
A48: Rural+Urban | B48: 2017 | C48: October | D48: 135.3 | E48: 142.2 | F48: 131.2 | G48: 140.6 | H48: 119 | I48: 141.5 | J48: 162.6 | K48: 132.3 | L48: 121.8 | M48: 136.3 | N48: 128.7 | O48: 148.1 | P48: 140.1 | Q48: 137.3 | R48: 132.2 | S48: 133.6 | T48: 131.3 | U48: 117.8 | V48: 128.4 | W48: 137.9 | X48: 126.2 | Y48: 127.7 | Z48: 136.1 | AA48: =SUM(Table14[[#This Row],[Cereals and products]:[Food and beverages]])/13 -> 136.9 | AB48: =SUM(Table14[[#This Row],[Fuel and light]]) -> 132.2 | AC48: =SUM(Table14[[#This Row],[Transport and communication]]) -> 117.8 | AD48: =SUM(Table14[[#This Row],[Housing]],Table14[[#This Row],[Household goods and services]])/2 -> 135.45 | AE48: =SUM(Table14[[#This Row],[Health]]) -> 131.3 | AF48: =SUM(Table14[[#This Row],[Recreation and amusement]],Table14[[#This Row],[Education]])/2 -> 133.15 | AG48: =SUM(Table14[[#This Row],[Miscellaneous]],Table14[[#This Row],[Personal care and effects]])/2 -> 126.95
A49: Rural | B49: 2017 | C49: October | D49: 135.9 | E49: 141.9 | F49: 131 | G49: 141.5 | H49: 121.4 | I49: 146.7 | J49: 157.1 | K49: 136.4 | L49: 121.4 | M49: 135.6 | N49: 131.3 | O49: 150.3 | P49: 140.4 | Q49: 137.3 | R49: 138.1 | S49: 138.4 | T49: 134.2 | U49: 121 | V49: 133 | W49: 140.1 | X49: 127.4 | Y49: 130.7 | Z49: 138.3 | AA49: =SUM(Table14[[#This Row],[Cereals and products]:[Food and beverages]])/13 -> 137.76154 | AB49: =SUM(Table14[[#This Row],[Fuel and light]]) -> 138.1 | AC49: =SUM(Table14[[#This Row],[Transport and communication]]) -> 121 | AD49: =SUM(Table14[[#This Row],[Housing]],Table14[[#This Row],[Household goods and services]])/2 -> 137.85 | AE49: =SUM(Table14[[#This Row],[Health]]) -> 134.2 | AF49: =SUM(Table14[[#This Row],[Recreation and amusement]],Table14[[#This Row],[Education]])/2 -> 136.55 | AG49: =SUM(Table14[[#This Row],[Miscellaneous]],Table14[[#This Row],[Personal care and effects]])/2 -> 129.05
A50: Urban | B50: 2016 | C50: October | D50: 128.7 | E50: 138.4 | F50: 130.3 | G50: 132.7 | H50: 112.5 | I50: 130.4 | J50: 155.1 | K50: 175.7 | L50: 115.4 | M50: 145.3 | N50: 122.5 | O50: 139.6 | P50: 136.3 | Q50: 128.7 | R50: 115.2 | S50: 124.5 | T50: 121.8 | U50: 112.8 | V50: 121.2 | W50: 131.9 | X50: 120.8 | Y50: 120.9 | Z50: 128.6 | AA50: =SUM(Table14[[#This Row],[Cereals and products]:[Food and beverages]])/13 -> 135.60769 | AB50: =SUM(Table14[[#This Row],[Fuel and light]]) -> 115.2 | AC50: =SUM(Table14[[#This Row],[Transport and communication]]) -> 112.8 | AD50: =SUM(Table14[[#This Row],[Housing]],Table14[[#This Row],[Household goods and services]])/2 -> 126.6 | AE50: =SUM(Table14[[#This Row],[Health]]) -> 121.8 | AF50: =SUM(Table14[[#This Row],[Recreation and amusement]],Table14[[#This Row],[Education]])/2 -> 126.55 | AG50: =SUM(Table14[[#This Row],[Miscellaneous]],Table14[[#This Row],[Personal care and effects]])/2 -> 120.85
...

Sheet Dataset(Highest Inflation rate 
A1: Details for Sum of Transportation2 - Month: December
A3: l | B3: Year | C3: Month | D3: Cereals and products | E3: Meat and fish | F3: Egg | G3: Milk and products | H3: Oils and fats | I3: Fruits | J3: Vegetables | K3: Pulses and products | L3: Sugar and Confectionery | M3: Spices | N3: Non-alcoholic beverages | O3: Prepared meals, snacks, sweets etc. | P3: Food and beverages | Q3: Housing | R3: Fuel and light | S3: Household goods and services | T3: Health | U3: Transport and communication | V3: Recreation and amusement | W3: Education | X3: Personal care and effects | Y3: Miscellaneous | Z3: General index | AA3: Food | AB3: Energy/Fuel | AC3: Transportation | AD3: Housing | AE3: Healthcare | AF3: Education & Recreation | AG3: Others | AH3: Year on- Year Inflation
A4: Urban | B4: 2013 | C4: December | D4: 120.5 | E4: 118.1 | F4: 128.5 | G4: 112.8 | H4: 103.4 | I4: 110.7 | J4: 144.8 | K4: 107.1 | L4: 98.6 | M4: 111.9 | N4: 112.1 | O4: 118.1 | P4: 117.8 | Q4: 110.7 | R4: 110.4 | S4: 111.3 | T4: 109 | U4: 109.7 | V4: 108.9 | W4: 111.4 | X4: 107.7 | Y4: 109.8 | Z4: 113.3 | AA4: 115.72308 | AB4: 110.4 | AC4: 109.7 | AD4: 111 | AE4: 109 | AF4: 110.15 | AG4: 108.75 | AH4: =Z23-Z20/Z20*100 -> 50.4
A5: Rural+Urban | B5: 2013 | C5: December | D5: 119.1 | E5: 116.7 | F5: 123.5 | G5: 113.4 | H5: 107.3 | I5: 113.3 | J5: 145.4 | K5: 108.7 | L5: 101.5 | M5: 110.5 | N5: 112.1 | O5: 117.4 | P5: 118.4 | Q5: 110.7 | R5: 111.9 | S5: 111.7 | T5: 109.7 | U5: 109.8 | V5: 109 | W5: 111.5 | X5: 107.9 | Y5: 110 | Z5: 114.5 | AA5: 115.94615 | AB5: 111.9 | AC5: 109.8 | AD5: 111.2 | AE5: 109.7 | AF5: 110.25 | AG5: 108.95 | AH5: =Z24-Z21/Z21*100 -> 58.9
A6: Rural | B6: 2013 | C6: December | D6: 118.4 | E6: 115.9 | F6: 120.4 | G6: 113.8 | H6: 109.5 | I6: 115.5 | J6: 145.7 | K6: 109.5 | L6: 102.9 | M6: 109.8 | N6: 112.1 | O6: 116.8 | P6: 118.7 | Q6: 110.7 | R6: 112.8 | S6: 112.1 | T6: 110.1 | U6: 109.9 | V6: 109.2 | W6: 111.6 | X6: 108.1 | Y6: 110.1 | Z6: 115.5 | AA6: 116.07692 | AB6: 112.8 | AC6: 109.9 | AD6: 111.4 | AE6: 110.1 | AF6: 110.4 | AG6: 109.1 | AH6: =Z25-Z22/Z22*100 -> 60.7
A7: Urban | B7: 2014 | C7: December | D7: 124 | E7: 124.7 | F7: 126.3 | G7: 124.9 | H7: 103 | I7: 122.3 | J7: 141 | K7: 120.1 | L7: 97.8 | M7: 125.4 | N7: 116.1 | O7: 127.6 | P7: 124 | Q7: 116.5 | R7: 113 | S7: 116.8 | T7: 113.2 | U7: 108.8 | V7: 114.3 | W7: 120.7 | X7: 110.4 | Y7: 113.4 | Z7: 118.4 | AA7: 121.32308 | AB7: 113 | AC7: 108.8 | AD7: 116.65 | AE7: 113.2 | AF7: 117.5 | AG7: 111.9 | AH7: =Z26-Z23/Z23*100 -> 41.9
A8: Rural+Urban | B8: 2014 | C8: December | D8: 122.9 | E8: 123.2 | F8: 123.5 | G8: 124.5 | H8: 107.6 | I8: 125.7 | J8: 140.5 | K8: 117.6 | L8: 100.6 | M8: 119.1 | N8: 116.8 | O8: 126.1 | P8: 123.6 | Q8: 116.5 | R8: 115.7 | S8: 117.5 | T8: 115.1 | U8: 110.1 | V8: 113.9 | W8: 119.5 | X8: 109.8 | Y8: 113.8 | Z8: 119.4 | AA8: 120.9 | AB8: 115.7 | AC8: 110.1 | AD8: 117 | AE8: 115.1 | AF8: 116.7 | AG8: 111.8 | AH8: =Z27-Z24/Z24*100 -> 52.3
A9: Urban | B9: 2015 | C9: December | D9: 124.3 | E9: 131.7 | F9: 127.1 | G9: 128.6 | H9: 110 | I9: 120.8 | J9: 149 | K9: 190.1 | L9: 92.7 | M9: 138.6 | N9: 120.2 | O9: 134.2 | P9: 131.5 | Q9: 122.4 | R9: 116 | S9: 121 | T9: 118.6 | U9: 109.3 | V9: 118.1 | W9: 126.6 | X9: 113.2 | Y9: 116.7 | Z9: 124 | AA9: 130.67692 | AB9: 116 | AC9: 109.3 | AD9: 121.7 | AE9: 118.6 | AF9: 122.35 | AG9: 114.95 | AH9: =Z28-Z25/Z25*100 -> 65.2
A10: Rural | B10: 2014 | C10: December | D10: 122.4 | E10: 122.4 | F10: 121.8 | G10: 124.2 | H10: 110.2 | I10: 128.6 | J10: 140.3 | K10: 116.3 | L10: 102 | M10: 116 | N10: 117.3 | O10: 124.8 | P10: 123.3 | Q10: 116.5 | R10: 117.4 | S10: 118.2 | T10: 116.2 | U10: 111.5 | V10: 113.3 | W10: 117.7 | X10: 109.4 | Y10: 114.2 | Z10: 120.3 | AA10: 120.73846 | AB10: 117.4 | AC10: 111.5 | AD10: 117.35 | AE10: 116.2 | AF10: 115.5 | AG10: 111.8 | AH10: =Z29-Z26/Z26*100 -> 66.2
A11: Urban | B11: 2016 | C11: December | D11: 131.6 | E11: 138.2 | F11: 134.9 | G11: 133.1 | H11: 113.5 | I11: 129.3 | J11: 121.1 | K11: 170.3 | L11: 115.5 | M11: 145.5 | N11: 123.1 | O11: 140.9 | P11: 132.8 | Q11: 128.5 | R11: 117.8 | S11: 125 | T11: 122.3 | U11: 113.7 | V11: 121.8 | W11: 132.3 | X11: 119.9 | Y11: 121.4 | Z11: 127.6 | AA11: 133.06154 | AB11: 117.8 | AC11: 113.7 | AD11: 126.75 | AE11: 122.3 | AF11: 127.05 | AG11: 120.65 | AH11: =Z30-Z27/Z27*100 -> 67
A12: Rural+Urban | B12: 2015 | C12: December | D12: 125.7 | E12: 131.4 | F12: 124.8 | G12: 129.4 | H12: 115.3 | I12: 126.6 | J12: 146.7 | K12: 171.5 | L12: 94.5 | M12: 132.1 | N12: 122 | O12: 134.7 | P12: 131.4 | Q12: 122.4 | R12: 122 | S12: 123.6 | T12: 121.4 | U12: 111.5 | V12: 119.6 | W12: 126.2 | X12: 113.7 | Y12: 118.3 | Z12: 126.1 | AA12: 129.7 | AB12: 122 | AC12: 111.5 | AD12: 123 | AE12: 121.4 | AF12: 122.9 | AG12: 116 | AH12: =Z31-Z28/Z28*100 -> 74.1
A13: Rural | B13: 2015 | C13: December | D13: 126.3 | E13: 131.3 | F13: 123.3 | G13: 129.8 | H13: 118.3 | I13: 131.6 | J13: 145.5 | K13: 162.1 | L13: 95.4 | M13: 128.9 | N13: 123.3 | O13: 135.1 | P13: 131.4 | Q13: 122.4 | R13: 125.7 | S13: 126 | T13: 123.1 | U13: 114 | V13: 121.6 | W13: 125.6 | X13: 114.1 | Y13: 119.8 | Z13: 127.9 | AA13: 129.40769 | AB13: 125.7 | AC13: 114 | AD13: 124.2 | AE13: 123.1 | AF13: 123.6 | AG13: 116.95 | AH13: =Z32-Z29/Z29*100 -> 75.7
A14: Rural+Urban | B14: 2016 | C14: December | D14: 132.3 | E14: 137.6 | F14: 132.9 | G14: 135.1 | H14: 118.6 | I14: 132.7 | J14: 125.3 | K14: 168.7 | L14: 114.4 | M14: 140.2 | N14: 126.6 | O14: 142.3 | P14: 134 | Q14: 128.5 | R14: 126.6 | S14: 129.2 | T14: 126.9 | U14: 116 | V14: 124.2 | W14: 133.1 | X14: 121.1 | Y14: 123.9 | Z14: 130.4 | AA14: 133.9 | AB14: 126.6 | AC14: 116 | AD14: 128.85 | AE14: 126.9 | AF14: 128.65 | AG14: 122.5 | AH14: =Z33-Z30/Z30*100 -> 77.1
A15: Urban | B15: 2017 | C15: December | D15: 134.4 | E15: 142.6 | F15: 145.9 | G15: 139.5 | H15: 115.9 | I15: 135 | J15: 163.2 | K15: 119.8 | L15: 120.7 | M15: 139.7 | N15: 125.7 | O15: 146.3 | P15: 138.8 | Q15: 139.1 | R15: 126.8 | S15: 129.3 | T15: 128.2 | U15: 115.3 | V15: 125.6 | W15: 136.7 | X15: 124.6 | Y15: 125.1 | Z15: 134.1 | AA15: 135.96154 | AB15: 126.8 | AC15: 115.3 | AD15: 134.2 | AE15: 128.2 | AF15: 131.15 | AG15: 124.85 | AH15: =Z34-Z31/Z31*100 -> -100
... A18: Urban | B18: 2019 | C18: December | D18: 144.9 | E18: 164.5 | F18: 153.7 | G18: 147.5 | H18: 122.7 | I18: 147.2 | J18: 231.5 | K18: 137.2 | L18: 114.7 | M18: 148 | N18: 130.8 | O18: 157.7 | P18: 156.3 | Q18: 152.8 | R18: 133.6 | S18: 139.8 | T18: 143.2 | U18: 125.2 | V18: 136.8 | W18: 151.9 | X18: 140.2 | Y18: 137.7 | Z18: 148.3 | AA18: 150.51538 | AB18: 133.6 | AC18: 125.2 | AD18: 146.3 | AE18: 143.2 | AF18: 144.35 | AG18: 138.95 | AH18: =Z37-Z34/Z34*100 -> #DIV/0!
A19: Rural+Urban | B19: 2017 | C19: December | D19: 135.8 | E19: 143.3 | F19: 145.2 | G19: 141 | H19: 120.5 | I19: 141.5 | J19: 161.7 | K19: 129.1 | L19: 121.5 | M19: 137.1 | N19: 128.8 | O19: 149 | P19: 140.5 | Q19: 139.1 | R19: 136.6 | S19: 134.7 | T19: 133.1 | U19: 118.5 | V19: 129 | W19: 138.5 | X19: 126.5 | Y19: 128.6 | Z19: 137.2 | AA19: 138.07692 | AB19: 136.6 | AC19: 118.5 | AD19: 136.9 | AE19: 133.1 | AF19: 133.75 | AG19: 127.55 | AH19: =Z22-Z19/Z19* 100 -> 40.1
A20: Urban | B20: 2020 | C20: December | D20: 149 | E20: 195.7 | F20: 178.3 | G20: 154.2 | H20: 140.7 | I20: 149.7 | J20: 240.9 | K20: 161.5 | L20: 117.1 | M20: 161.9 | N20: 143.3 | O20: 166.1 | P20: 167 | Q20: 158.4 | R20: 137.9 | S20: 145.5 | T20: 152.9 | U20: 135.5 | V20: 144.3 | W20: 156.9 | X20: 157.9 | Y20: 146.9 | Z20: 156.9 | AA20: 163.49231 | AB20: 137.9 | AC20: 135.5 | AD20: 151.95 | AE20: 152.9 | AF20: 150.6 | AG20: 152.4 | AH20: =Z23-Z20/Z20* 100 -> 50.4
A21: Rural | B21: 2017 | C21: December | D21: 136.4 | E21: 143.7 | F21: 144.8 | G21: 141.9 | H21: 123.1 | I21: 147.2 | J21: 161 | K21: 133.8 | L21: 121.9 | M21: 135.8 | N21: 131.1 | O21: 151.4 | P21: 141.5 | Q21: 139.1 | R21: 142.6 | S21: 139.5 | T21: 136.1 | U21: 122 | V21: 133.4 | W21: 141.1 | X21: 127.8 | Y21: 131.9 | Z21: 139.8 | AA21: 139.50769 | AB21: 142.6 | AC21: 122 | AD21: 139.3 | AE21: 136.1 | AF21: 137.25 | AG21: 129.85 | AH21: =Z24-Z21/Z21* 100 -> 58.9
A22: Rural+Urban | B22: 2018 | C22: December | D22: 137.5 | E22: 150.5 | F22: 138.8 | G22: 142.1 | H22: 122 | I22: 139.4 | J22: 135.2 | K22: 119.8 | L22: 110.3 | M22: 140.6 | N22: 133.8 | O22: 154.6 | P22: 138.2 | Q22: 146.5 | R22: 142.7 | S22: 143.2 | T22: 144.9 | U22: 123.6 | V22: 136.8 | W22: 150.1 | X22: 132.2 | Y22: 136.8 | Z22: 140.1 | AA22: 135.6 | AB22: 142.7 | AC22: 123.6 | AD22: 144.85 | AE22: 144.9 | AF22: 143.45 | AG22: 134.5 | AH22: =Z25-Z22/Z22* 100 -> 60.7
A23: Rural+Urban | B23: 2019 | C23: December | D23: 143.5 | E23: 165 | F23: 151.1 | G23: 148.3 | H23: 125.7 | I23: 145.7 | J23: 217 | K23: 138.3 | L23: 114 | M23: 148.7 | N23: 135.8 | O23: 158 | P23: 155 | Q23: 152.8 | R23: 143.7 | S23: 145.8 | T23: 150.4 | U23: 129.8 | V23: 142.3 | W23: 155.7 | X23: 140.4 | Y23: 142.5 | Z23: 150.4 | AA23: 149.7 | AB23: 143.7 | AC23: 129.8 | AD23: 149.3 | AE23: 150.4 | AF23: 149 | AG23: 141.45 | AH23: =Z26-Z23/Z23* 100 -> 41.9
A24: Rural+Urban | B24: 2020 | C24: December | D24: 146 | E24: 191 | F24: 175.3 | G24: 154.1 | H24: 146.6 | I24: 147.7 | J24: 230.5 | K24: 160.2 | L24: 115.3 | M24: 163 | N24: 149.2 | O24: 164.8 | P24: 165.4 | Q24: 158.4 | R24: 144.6 | S24: 149.7 | T24: 158.3 | U24: 140.7 | V24: 148.5 | W24: 159.4 | X24: 157.1 | Y24: 151.2 | Z24: 158.9 | AA24: 162.23846 | AB24: 144.6 | AC24: 140.7 | AD24: 154.05 | AE24: 158.3 | AF24: 153.95 | AG24: 154.15 | AH24: =Z27-Z24/Z24* 100 -> 52.3
A25: Rural | B25: 2020 | C25: December | D25: 144.6 | E25: 188.5 | F25: 173.4 | G25: 154 | H25: 150 | I25: 145.9 | J25: 225.2 | K25: 159.5 | L25: 114.4 | M25: 163.5 | N25: 153.4 | O25: 163.6 | P25: 164.5 | Q25: 158.4 | R25: 148.7 | S25: 153.4 | T25: 161.6 | U25: 146.4 | V25: 153.9 | W25: 162.9 | X25: 156.6 | Y25: 155.2 | Z25: 160.7 | AA25: 161.57692 | AB25: 148.7 | AC25: 146.4 | AD25: 155.9 | AE25: 161.6 | AF25: 158.4 | AG25: 155.9 | AH25: =Z28-Z25/Z25* 100 -> 65.2
A26: Rural | B26: 2018 | C26: December | D26: 137.1 | E26: 151.9 | F26: 137.4 | G26: 142.4 | H26: 124.2 | I26: 140.2 | J26: 136.6 | K26: 120.9 | L26: 109.9 | M26: 140.2 | N26: 137.8 | O26: 156 | P26: 138.5 | Q26: 146.5 | R26: 149 | S26: 149.5 | T26: 149.6 | U26: 128.9 | V26: 143.3 | W26: 155.1 | X26: 133.2 | Y26: 141.6 | Z26: 141.9 | AA26: 136.39231 | AB26: 149 | AC26: 128.9 | AD26: 148 | AE26: 149.6 | AF26: 149.2 | AG26: 137.4 | AH26: =Z29-Z26/Z26* 100 -> 66.2
A27: Rural | B27: 2019 | C27: December | D27: 142.8 | E27: 165.3 | F27: 149.5 | G27: 148.7 | H27: 127.5 | I27: 144.3 | J27: 209.5 | K27: 138.8 | L27: 113.6 | M27: 149.1 | N27: 139.3 | O27: 158.3 | P27: 154.3 | Q27: 152.8 | R27: 149.9 | S27: 151.2 | T27: 154.8 | U27: 135 | V27: 149.5 | W27: 161.1 | X27: 140.6 | Y27: 147.1 | Z27: 152.3 | AA27: 149.30769 | AB27: 149.9 | AC27: 135 | AD27: 152 | AE27: 154.8 | AF27: 155.3 | AG27: 143.85 | AH27: =Z30-Z27/Z27* 100 -> 67
A28: Urban | B28: 2021 | C28: December | D28: 151.6 | E28: 202.2 | F28: 180 | G28: 160 | H28: 173.5 | I28: 158.3 | J28: 219.5 | K28: 164.2 | L28: 121.9 | M28: 168.2 | N28: 156.5 | O28: 178.2 | P28: 172.2 | Q28: 163.4 | R28: 161.7 | S28: 156 | T28: 165.1 | U28: 151.8 | V28: 157.6 | W28: 160.6 | X28: 162.4 | Y28: 157.8 | Z28: 165.2 | AA28: 169.71538 | AB28: 161.7 | AC28: 151.8 | AD28: 159.7 | AE28: 165.1 | AF28: 159.1 | AG28: 160.1 | AH28: =Z31-Z28/Z28* 100 -> 74.1
A29: Rural+Urban | B29: 2021 | C29: December | D29: 148.7 | E29: 198.8 | F29: 177.9 | G29: 159.9 | H29: 187.6 | I29: 154.9 | J29: 188.3 | K29: 164.4 | L29: 121 | M29: 170.5 | N29: 164.2 | O29: 176.5 | P29: 168.2 | Q29: 163.4 | R29: 164.1 | S29: 160.2 | T29: 170.6 | U29: 155.7 | V29: 160.6 | W29: 164.4 | X29: 162.6 | Y29: 162 | Z29: 166.2 | AA29: 167.76154 | AB29: 164.1 | AC29: 155.7 | AD29: 161.8 | AE29: 170.6 | AF29: 162.5 | AG29: 162.3 | AH29: =Z32-Z29/Z29* 100 -> 75.7
A30: Rural | B30: 2021 | C30: December | D30: 147.4 | E30: 197 | F30: 176.5 | G30: 159.8 | H30: 195.8 | I30: 152 | J30: 172.3 | K30: 164.5 | L30: 120.6 | M30: 171.7 | N30: 169.7 | O30: 175.1 | P30: 165.8 | Q30: 163.4 | R30: 165.6 | S30: 163.9 | T30: 174 | U30: 160.1 | V30: 164.5 | W30: 169.7 | X30: 162.8 | Y30: 166 | Z30: 167 | AA30: 166.78462 | AB30: 165.6 | AC30: 160.1 | AD30: 163.65 | AE30: 174 | AF30: 167.1 | AG30: 164.4 | AH30: =Z33-Z30/Z30* 100 -> 77.1
... A32: Rural+Urban | B32: 2022 | C32: December | D32: 169.2 | E32: 209 | F32: 190.2 | G32: 173.6 | H32: 188.5 | I32: 158 | J32: 159.9 | K32: 170.8 | L32: 121.8 | M32: 205.2 | N32: 171 | O32: 190.3 | P32: 175.9 | Q32: 170.7 | R32: 182 | S32: 172.1 | T32: 181.1 | U32: 163.4 | V32: 168.9 | W32: 174.1 | X32: 175.8 | Y32: 172 | Z32: 175.7 | AA32: 175.64615 | AB32: 182 | AC32: 163.4 | AD32: 171.4 | AE32: 181.1 | AF32: 171.5 | AG32: 173.9 | AH32: =Z35-Z32/Z32* 100 -> -100
A33: Rural | B33: 2022 | C33: December | D33: 168.8 | E33: 206.9 | F33: 189.1 | G33: 173.4 | H33: 193.9 | I33: 156.7 | J33: 150.2 | K33: 170.5 | L33: 121.2 | M33: 207.5 | N33: 176.8 | O33: 187.7 | P33: 174.4 | Q33: 170.7 | R33: 182.8 | S33: 176.4 | T33: 183.5 | U33: 167.8 | V33: 171.2 | W33: 177.3 | X33: 175.7 | Y33: 175.5 | Z33: 177.1 | AA33: 175.16154 | AB33: 182.8 | AC33: 167.8 | AD33: 173.55 | AE33: 183.5 | AF33: 174.25 | AG33: 175.6
A36: Q2: Problem Statement 2.
B38: Year | D38: YEAR _ YEAR INFLATION_RATE
B39: 2017 | D39: =Z22-Z19/Z19 * 100 -> 40.1
B40: 2018 | D40: =Z23-Z20/Z20 * 100 -> 50.4
B41: 2019 | D41: =Z24-Z21/Z21 * 100 -> 58.9
B42: 2020 | C42: (Highest Inflation Rate) | D42: =Z25-Z22/Z22 * 100 -> 60.7
B43: 2021 | D43: =Z26-Z23/Z23 * 100 -> 41.9
B44: 2022 | D44: =Z27-Z24/Z24 * 100 -> 52.3
A46: YEAR | B46: 2020 | C46: was having the | D46: HIGHEST INFLATION RATE WHICH IS = 60.7
D49: +

Sheet Highest Category Contributor in

Sheet PROBLEM_STATEMENT_1
A1: Month | B1: December | F1: Last Month we have Taken as December | H1: Calculate Each Price Index Category Percentage Value | I1: List of Categories
A3: Row Labels | B3: Sum of Transportation2 | C3: Sum of Food | D3: Sum of Energy/Fuel | F3: (CHECK THE HIGHEST CPI INFLATION RATE OF THE WHICH CATEGORY)
A4: 108.8 | B4: 108.8 | C4: 121.32308 | D4: 113 | F4: =SUM(3840.8+4290.39+4146.6) -> 12277.79 | G4: Total SUM OF all Categories | H4: =(4290.39/12277.79) * 100 -> 34.944318 | I4: Food (Highest Inflation Contributor)
A5: 121.32308 | B5: 108.8 | C5: 121.32308 | D5: 113 | H5: =(3840.8/12277.79* 100) -> 31.282503 | I5: Transportation
A6: 113 | B6: 108.8 | C6: 121.32308 | D6: 113 | F6: Transportation = (3840.80) | H6: =(4146.6/12277.79 *100) -> 33.773179 | I6: Energy/Fuel
A7: 109.3 | B7: 109.3 | C7: 130.67692 | D7: 116 | F7: Food = (4290.39)
A8: 130.67692 | B8: 109.3 | C8: 130.67692 | D8: 116 | F8: Energy/Fuel = (4146.60)
A9: 116 | B9: 109.3 | C9: 130.67692 | D9: 116
A10: 109.7 | B10: 109.7 | C10: 115.72308 | D10: 110.4
A11: 115.72308 | B11: 109.7 | C11: 115.72308 | D11: 110.4 | H11: The Price Rise of the food category is the highest among all other three categories which is 34.94 %,
A12: 110.4 | B12: 109.7 | C12: 115.72308 | D12: 110.4
A13: 109.8 | B13: 109.8 | C13: 115.94615 | D13: 111.9
A14: 115.94615 | B14: 109.8 | C14: 115.94615 | D14: 111.9
A15: 111.9 | B15: 109.8 | C15: 115.94615 | D15: 111.9
A16: 109.9 | B16: 109.9 | C16: 116.07692 | D16: 112.8
A17: 116.07692 | B17: 109.9 | C17: 116.07692 | D17: 112.8
A18: 112.8 | B18: 109.9 | C18: 116.07692 | D18: 112.8
A19: 110.1 | B19: 110.1 | C19: 120.9 | D19: 115.7
A20: 120.9 | B20: 110.1 | C20: 120.9 | D20: 115.7
A21: 115.7 | B21: 110.1 | C21: 120.9 | D21: 115.7
A22: 111.5 | B22: 223 | C22: 250.43846 | D22: 239.4
A23: 120.73846 | B23: 111.5 | C23: 120.73846 | D23: 117.4
... A92: 182.8 | B92: 167.8 | C92: 175.16154 | D92: 182.8
A93: Grand Total | B93: 3840.8 | C93: 4290.3923 | D93: 4146.6

Sheet Problem Statement 3)
A1: Sector | B1: Year | C1: Month | D1: Cereals and products | E1: Meat and fish | F1: Egg | G1: Milk and products | H1: Oils and fats | I1: Fruits | J1: Vegetables | K1: Pulses and products | L1: Sugar and Confectionery | M1: Spices | N1: Non-alcoholic beverages | O1: Prepared meals, snacks, sweets etc. | P1: Food and beverages | Q1: Housing | R1: Fuel and light | S1: Household goods and services | T1: Health | U1: Transport and communication | V1: Recreation and amusement | W1: Education | X1: Personal care and effects | Y1: Miscellaneous | Z1: General index | AA1: Food | AB1: Energy/Fuel | AC1: Transportation | AD1: Housing | AE1: Healthcare | AF1: Education & Recreation | AG1: Others
A2: Rural | B2: 2022 | C2: September | D2: 162.9 | E2: 206.7 | F2: 169 | G2: 169.5 | H2: 194.1 | I2: 164.1 | J2: 176.9 | K2: 169 | L2: 120.8 | M2: 199.1 | N2: 175.4 | O2: 184.8 | P2: 175.5 | Q2: 162.1 | R2: 179.7 | S2: 173.6 | T2: 180.2 | U2: 166.9 | V2: 170 | W2: 176.2 | X2: 170.8 | Y2: 173.1 | Z2: 176.4 | AA2: =SUM(Table1[[#This Row],[Cereals and products]:[Food and beverages]])/13 -> 174.44615 | AB2: =SUM(Table1[[#This Row],[Fuel and light]]) -> 179.7 | AC2: =SUM(Table1[[#This Row],[Transport and communication]]) -> 166.9 | AD2: =SUM(Table1[[#This Row],[Housing]],Table1[[#This Row],[Household goods and services]])/2 -> 167.85 | AE2: =SUM(Table1[[#This Row],[Health]]) -> 180.2 | AF2: =SUM(Table1[[#This Row],[Recreation and amusement]],Table1[[#This Row],[Education]])/2 -> 173.1 | AG2: =SUM(Table1[[#This Row],[Miscellaneous]],Table1[[#This Row],[Personal care and effects]])/2 -> 171.95
A3: Rural+Urban | B3: 2022 | C3: September | D3: 163.5 | E3: 209.2 | F3: 169.7 | G3: 169.7 | H3: 188.7 | I3: 165.7 | J3: 191.8 | K3: 169.1 | L3: 121.6 | M3: 197.3 | N3: 169.4 | O3: 187.4 | P3: 177.8 | Q3: 169.5 | R3: 179.5 | S3: 169.5 | T3: 177.8 | U3: 162.3 | V3: 167.6 | W3: 173.1 | X3: 170.9 | Y3: 169.7 | Z3: 175.3 | AA3: =SUM(Table1[[#This Row],[Cereals and products]:[Food and beverages]])/13 -> 175.45385 | AB3: =SUM(Table1[[#This Row],[Fuel and light]]) -> 179.5 | AC3: =SUM(Table1[[#This Row],[Transport and communication]]) -> 162.3 | AD3: =SUM(Table1[[#This Row],[Housing]],Table1[[#This Row],[Household goods and services]])/2 -> 169.5 | AE3: =SUM(Table1[[#This Row],[Health]]) -> 177.8 | AF3: =SUM(Table1[[#This Row],[Recreation and amusement]],Table1[[#This Row],[Education]])/2 -> 170.35 | AG3: =SUM(Table1[[#This Row],[Miscellaneous]],Table1[[#This Row],[Personal care and effects]])/2 -> 170.3
A4: Urban | B4: 2022 | C4: September | D4: 164.9 | E4: 213.7 | F4: 170.9 | G4: 170.1 | H4: 179.3 | I4: 167.5 | J4: 220.8 | K4: 169.2 | L4: 123.1 | M4: 193.6 | N4: 161.1 | O4: 190.4 | P4: 181.8 | Q4: 169.5 | R4: 179.2 | S4: 165 | T4: 173.8 | U4: 158.2 | V4: 165.8 | W4: 170.9 | X4: 171.1 | Y4: 166.1 | Z4: 174.1 | AA4: =SUM(Table1[[#This Row],[Cereals and products]:[Food and beverages]])/13 -> 177.41538 | AB4: =SUM(Table1[[#This Row],[Fuel and light]]) -> 179.2 | AC4: =SUM(Table1[[#This Row],[Transport and communication]]) -> 158.2 | AD4: =SUM(Table1[[#This Row],[Housing]],Table1[[#This Row],[Household goods and services]])/2 -> 167.25 | AE4: =SUM(Table1[[#This Row],[Health]]) -> 173.8 | AF4: =SUM(Table1[[#This Row],[Recreation and amusement]],Table1[[#This Row],[Education]])/2 -> 168.35 | AG4: =SUM(Table1[[#This Row],[Miscellaneous]],Table1[[#This Row],[Personal care and effects]])/2 -> 168.6
A5: Rural | B5: 2019 | C5: August | D5: 139.2 | E5: 161.9 | F5: 137.1 | G5: 144.6 | H5: 124.7 | I5: 145.5 | J5: 156.2 | K5: 131.5 | L5: 111.7 | M5: 142.7 | N5: 138.5 | O5: 156.9 | P5: 144 | Q5: =AVERAGE(Q6:Q7) -> 151.6 | R5: 146.4 | S5: 150.2 | T5: 152.7 | U5: 131.4 | V5: 148 | W5: 159.7 | X5: 138.8 | Y5: 144.9 | Z5: 145.7 | AA5: =SUM(Table1[[#This Row],[Cereals and products]:[Food and beverages]])/13 -> 141.11538 | AB5: =SUM(Table1[[#This Row],[Fuel and light]]) -> 146.4 | AC5: =SUM(Table1[[#This Row],[Transport and communication]]) -> 131.4 | AD5: =SUM(Table1[[#This Row],[Housing]],Table1[[#This Row],[Household goods and services]])/2 -> 150.9 | AE5: =SUM(Table1[[#This Row],[Health]]) -> 152.7 | AF5: =SUM(Table1[[#This Row],[Recreation and amusement]],Table1[[#This Row],[Education]])/2 -> 153.85 | AG5: =SUM(Table1[[#This Row],[Miscellaneous]],Table1[[#This Row],[Personal care and effects]])/2 -> 141.85
A6: Rural+Urban | B6: 2019 | C6: August | D6: 140.1 | E6: 160.6 | F6: 138.5 | G6: 144.7 | H6: 122.9 | I6: 149.4 | J6: 167.4 | K6: 130.9 | L6: 112 | M6: 142.6 | N6: 134.9 | O6: 156.6 | P6: 145.9 | Q6: 151.6 | R6: 138.5 | S6: 144.5 | T6: 148.5 | U6: 125.8 | V6: 140.9 | W6: 154.9 | X6: 138.4 | Y6: 140.2 | Z6: 145 | AA6: =SUM(Table1[[#This Row],[Cereals and products]:[Food and beverages]])/13 -> 142.03846 | AB6: =SUM(Table1[[#This Row],[Fuel and light]]) -> 138.5 | AC6: =SUM(Table1[[#This Row],[Transport and communication]]) -> 125.8 | AD6: =SUM(Table1[[#This Row],[Housing]],Table1[[#This Row],[Household goods and services]])/2 -> 148.05 | AE6: =SUM(Table1[[#This Row],[Health]]) -> 148.5 | AF6: =SUM(Table1[[#This Row],[Recreation and amusement]],Table1[[#This Row],[Education]])/2 -> 147.9 | AG6: =SUM(Table1[[#This Row],[Miscellaneous]],Table1[[#This Row],[Personal care and effects]])/2 -> 139.3
A7: Urban | B7: 2019 | C7: August | D7: 142.1 | E7: 158.3 | F7: 140.8 | G7: 144.9 | H7: 119.9 | I7: 153.9 | J7: 189.1 | K7: 129.8 | L7: 112.7 | M7: 142.5 | N7: 129.8 | O7: 156.2 | P7: 149.1 | Q7: 151.6 | R7: 125.5 | S7: 138.1 | T7: 141.5 | U7: 120.8 | V7: 135.4 | W7: 151.5 | X7: 137.8 | Y7: 135.3 | Z7: 144.2 | AA7: =SUM(Table1[[#This Row],[Cereals and products]:[Food and beverages]])/13 -> 143.77692 | AB7: =SUM(Table1[[#This Row],[Fuel and light]]) -> 125.5 | AC7: =SUM(Table1[[#This Row],[Transport and communication]]) -> 120.8 | AD7: =SUM(Table1[[#This Row],[Housing]],Table1[[#This Row],[Household goods and services]])/2 -> 144.85 | AE7: =SUM(Table1[[#This Row],[Health]]) -> 141.5 | AF7: =SUM(Table1[[#This Row],[Recreation and amusement]],Table1[[#This Row],[Education]])/2 -> 143.45 | AG7: =SUM(Table1[[#This Row],[Miscellaneous]],Table1[[#This Row],[Personal care and effects]])/2 -> 136.55
